Traceback (most recent call last):
  File "/opt/hostedtoolcache/Python/3.8.12/x64/lib/python3.8/site-packages/jupyter_cache/executors/utils.py", line 51, in single_nb_execution
    executenb(
  File "/opt/hostedtoolcache/Python/3.8.12/x64/lib/python3.8/site-packages/nbclient/client.py", line 1085, in execute
    return NotebookClient(nb=nb, resources=resources, km=km, **kwargs).execute()
  File "/opt/hostedtoolcache/Python/3.8.12/x64/lib/python3.8/site-packages/nbclient/util.py", line 84, in wrapped
    return just_run(coro(*args, **kwargs))
  File "/opt/hostedtoolcache/Python/3.8.12/x64/lib/python3.8/site-packages/nbclient/util.py", line 62, in just_run
    return loop.run_until_complete(coro)
  File "/opt/hostedtoolcache/Python/3.8.12/x64/lib/python3.8/asyncio/base_events.py", line 616, in run_until_complete
    return future.result()
  File "/opt/hostedtoolcache/Python/3.8.12/x64/lib/python3.8/site-packages/nbclient/client.py", line 551, in async_execute
    await self.async_execute_cell(
  File "/opt/hostedtoolcache/Python/3.8.12/x64/lib/python3.8/site-packages/nbclient/client.py", line 846, in async_execute_cell
    self._check_raise_for_error(cell, exec_reply)
  File "/opt/hostedtoolcache/Python/3.8.12/x64/lib/python3.8/site-packages/nbclient/client.py", line 748, in _check_raise_for_error
    raise CellExecutionError.from_cell_and_msg(cell, exec_reply_content)
nbclient.exceptions.CellExecutionError: An error occurred while executing the following cell:
------------------
import os
import sys
import inspect

currentdir = os.path.dirname(os.path.abspath(inspect.getfile(inspect.currentframe())))
parentdir = os.path.dirname(currentdir)
sys.path.insert(0, parentdir) 

# data generation modules
from sklearn.datasets import make_circles
from sklearn.model_selection import train_test_split


# plotting
import matplotlib.pyplot as plt
from PythonFiles.plotting import plot_classes #plot_contour

# mathematical
import numpy as np
import math
------------------

[0;31m---------------------------------------------------------------------------[0m
[0;31mModuleNotFoundError[0m                       Traceback (most recent call last)
[0;32m/tmp/ipykernel_1917/2263512856.py[0m in [0;36m<module>[0;34m[0m
[1;32m      8[0m [0;34m[0m[0m
[1;32m      9[0m [0;31m# data generation modules[0m[0;34m[0m[0;34m[0m[0;34m[0m[0m
[0;32m---> 10[0;31m [0;32mfrom[0m [0msklearn[0m[0;34m.[0m[0mdatasets[0m [0;32mimport[0m [0mmake_circles[0m[0;34m[0m[0;34m[0m[0m
[0m[1;32m     11[0m [0;32mfrom[0m [0msklearn[0m[0;34m.[0m[0mmodel_selection[0m [0;32mimport[0m [0mtrain_test_split[0m[0;34m[0m[0;34m[0m[0m
[1;32m     12[0m [0;34m[0m[0m

[0;31mModuleNotFoundError[0m: No module named 'sklearn'
ModuleNotFoundError: No module named 'sklearn'

